ERROR:root:An error occurred:
Traceback (most recent call last):
  File "/home/ec2-user/workspace/cf_rank/main.py", line 233, in <module>
    main(args)
  File "/home/ec2-user/workspace/cf_rank/main.py", line 205, in main
    trainer.evaluator.plot_train_val(log_file_path=args.output_dir+'/out.log',output_image_path=args.output_dir+'/eval_train_val.jpg')
  File "/home/ec2-user/workspace/cf_rank/engine.py", line 511, in plot_train_val
    plt.plot(epochs, train_acc, label='Train Accuracy', marker='o')
  File "/home/ec2-user/anaconda3/envs/rank3/lib/python3.9/site-packages/matplotlib/pyplot.py", line 3794, in plot
    return gca().plot(
  File "/home/ec2-user/anaconda3/envs/rank3/lib/python3.9/site-packages/matplotlib/axes/_axes.py", line 1779, in plot
    lines = [*self._get_lines(self, *args, data=data, **kwargs)]
  File "/home/ec2-user/anaconda3/envs/rank3/lib/python3.9/site-packages/matplotlib/axes/_base.py", line 296, in __call__
    yield from self._plot_args(
  File "/home/ec2-user/anaconda3/envs/rank3/lib/python3.9/site-packages/matplotlib/axes/_base.py", line 486, in _plot_args
    raise ValueError(f"x and y must have same first dimension, but "
ValueError: x and y must have same first dimension, but have shapes (0,) and (25,)
