ERROR:root:An error occurred:
Traceback (most recent call last):
  File "/home/ec2-user/workspace/cf_rank/main.py", line 229, in <module>
    main(args)
  File "/home/ec2-user/workspace/cf_rank/main.py", line 183, in main
    trainer = local_trainer(train_loader=train_dataloader,val_loader=test_dataloader,
  File "/home/ec2-user/workspace/cf_rank/engine.py", line 59, in __init__
    self.resume(load_path=args.load_path, model='arranger')
  File "/home/ec2-user/workspace/cf_rank/engine.py", line 397, in resume
    missing_keys, unexpected_keys = self.arranger.load_state_dict(checkpoint['model'], strict=False)
  File "/home/ec2-user/anaconda3/envs/rank3/lib/python3.9/site-packages/torch/nn/modules/module.py", line 2215, in load_state_dict
    raise RuntimeError('Error(s) in loading state_dict for {}:\n\t{}'.format(
RuntimeError: Error(s) in loading state_dict for BertArranger:
	size mismatch for classifier.weight: copying a param with shape torch.Size([1, 1560]) from checkpoint, the shape in current model is torch.Size([1, 780]).
