ERROR:root:An error occurred:
Traceback (most recent call last):
  File "/home/ec2-user/workspace/cf_rank/main.py", line 233, in <module>
    main(args)
  File "/home/ec2-user/workspace/cf_rank/main.py", line 196, in main
    trainer.resume(load_path=args.load_path, model='reward')
  File "/home/ec2-user/workspace/cf_rank/engine.py", line 406, in resume
    checkpoint = torch.load(load_path, map_location='cpu')
  File "/home/ec2-user/anaconda3/envs/rank3/lib/python3.9/site-packages/torch/serialization.py", line 1065, in load
    with _open_file_like(f, 'rb') as opened_file:
  File "/home/ec2-user/anaconda3/envs/rank3/lib/python3.9/site-packages/torch/serialization.py", line 468, in _open_file_like
    return _open_file(name_or_buffer, mode)
  File "/home/ec2-user/anaconda3/envs/rank3/lib/python3.9/site-packages/torch/serialization.py", line 449, in __init__
    super().__init__(open(name, mode))
FileNotFoundError: [Errno 2] No such file or directory: '/home/ec2-user/workspace/outputs/rr_org_pre_hard/checkpoints/checkpoint35.pth'
ERROR:root:An error occurred:
Traceback (most recent call last):
  File "/home/ec2-user/workspace/cf_rank/main.py", line 233, in <module>
    main(args)
  File "/home/ec2-user/workspace/cf_rank/main.py", line 196, in main
    trainer.resume(load_path=args.load_path, model='reward')
  File "/home/ec2-user/workspace/cf_rank/engine.py", line 406, in resume
    checkpoint = torch.load(load_path, map_location='cpu')
  File "/home/ec2-user/anaconda3/envs/rank3/lib/python3.9/site-packages/torch/serialization.py", line 1065, in load
    with _open_file_like(f, 'rb') as opened_file:
  File "/home/ec2-user/anaconda3/envs/rank3/lib/python3.9/site-packages/torch/serialization.py", line 468, in _open_file_like
    return _open_file(name_or_buffer, mode)
  File "/home/ec2-user/anaconda3/envs/rank3/lib/python3.9/site-packages/torch/serialization.py", line 449, in __init__
    super().__init__(open(name, mode))
FileNotFoundError: [Errno 2] No such file or directory: '/home/ec2-user/workspace/outputs/rr_org_pre_hard/checkpoints/checkpoint35.pth'
ERROR:root:An error occurred:
Traceback (most recent call last):
  File "/home/ec2-user/workspace/cf_rank/main.py", line 233, in <module>
    main(args)
  File "/home/ec2-user/workspace/cf_rank/main.py", line 196, in main
    trainer.resume(load_path=args.load_path, model='reward')
  File "/home/ec2-user/workspace/cf_rank/engine.py", line 406, in resume
    checkpoint = torch.load(load_path, map_location='cpu')
  File "/home/ec2-user/anaconda3/envs/rank3/lib/python3.9/site-packages/torch/serialization.py", line 1065, in load
    with _open_file_like(f, 'rb') as opened_file:
  File "/home/ec2-user/anaconda3/envs/rank3/lib/python3.9/site-packages/torch/serialization.py", line 468, in _open_file_like
    return _open_file(name_or_buffer, mode)
  File "/home/ec2-user/anaconda3/envs/rank3/lib/python3.9/site-packages/torch/serialization.py", line 449, in __init__
    super().__init__(open(name, mode))
FileNotFoundError: [Errno 2] No such file or directory: '/home/ec2-user/workspace/outputs/rr_org_pre_hard/checkpoints/checkpoint35.pth'
ERROR:root:An error occurred:
Traceback (most recent call last):
  File "/home/ec2-user/workspace/cf_rank/main.py", line 233, in <module>
    main(args)
  File "/home/ec2-user/workspace/cf_rank/main.py", line 196, in main
    trainer.resume(load_path=args.load_path, model='reward')
  File "/home/ec2-user/workspace/cf_rank/engine.py", line 406, in resume
    checkpoint = torch.load(load_path, map_location='cpu')
  File "/home/ec2-user/anaconda3/envs/rank3/lib/python3.9/site-packages/torch/serialization.py", line 1065, in load
    with _open_file_like(f, 'rb') as opened_file:
  File "/home/ec2-user/anaconda3/envs/rank3/lib/python3.9/site-packages/torch/serialization.py", line 468, in _open_file_like
    return _open_file(name_or_buffer, mode)
  File "/home/ec2-user/anaconda3/envs/rank3/lib/python3.9/site-packages/torch/serialization.py", line 449, in __init__
    super().__init__(open(name, mode))
FileNotFoundError: [Errno 2] No such file or directory: '/home/ec2-user/workspace/outputs/rr_org_pre_hard/checkpoints/checkpoint35.pth'
ERROR:root:An error occurred:
Traceback (most recent call last):
  File "/home/ec2-user/workspace/cf_rank/main.py", line 233, in <module>
    main(args)
  File "/home/ec2-user/workspace/cf_rank/main.py", line 196, in main
    trainer.resume(load_path=args.load_path, model='reward')
  File "/home/ec2-user/workspace/cf_rank/engine.py", line 406, in resume
    checkpoint = torch.load(load_path, map_location='cpu')
  File "/home/ec2-user/anaconda3/envs/rank3/lib/python3.9/site-packages/torch/serialization.py", line 1065, in load
    with _open_file_like(f, 'rb') as opened_file:
  File "/home/ec2-user/anaconda3/envs/rank3/lib/python3.9/site-packages/torch/serialization.py", line 468, in _open_file_like
    return _open_file(name_or_buffer, mode)
  File "/home/ec2-user/anaconda3/envs/rank3/lib/python3.9/site-packages/torch/serialization.py", line 449, in __init__
    super().__init__(open(name, mode))
FileNotFoundError: [Errno 2] No such file or directory: '/home/ec2-user/workspace/outputs/rr_org_pre_hard/checkpoints/checkpoint35.pth'
