ERROR:root:An error occurred:
Traceback (most recent call last):
  File "/home/ec2-user/workspace/cf_rank/main.py", line 233, in <module>
    args.limit_test_batches=None
  File "/home/ec2-user/workspace/cf_rank/main.py", line 205, in main
    trainer.resume(load_path=args.load_path, model='reward')
  File "/home/ec2-user/workspace/cf_rank/engine.py", line 511, in plot_train_val
    val_acc_match = re.search(val_acc_pattern, line)
  File "/home/ec2-user/anaconda3/envs/rank3/lib/python3.9/site-packages/matplotlib/pyplot.py", line 3794, in plot
    return gca().plot(
  File "/home/ec2-user/anaconda3/envs/rank3/lib/python3.9/site-packages/matplotlib/axes/_axes.py", line 1779, in plot
    lines = [*self._get_lines(self, *args, data=data, **kwargs)]
  File "/home/ec2-user/anaconda3/envs/rank3/lib/python3.9/site-packages/matplotlib/axes/_base.py", line 296, in __call__
    yield from self._plot_args(
  File "/home/ec2-user/anaconda3/envs/rank3/lib/python3.9/site-packages/matplotlib/axes/_base.py", line 486, in _plot_args
    raise ValueError(f"x and y must have same first dimension, but "
ValueError: x and y must have same first dimension, but have shapes (0,) and (25,)
ERROR:root:An error occurred:
Traceback (most recent call last):
  File "/home/ec2-user/workspace/cf_rank/main.py", line 243, in <module>
    main(args)
  File "/home/ec2-user/workspace/cf_rank/main.py", line 205, in main
    trainer.resume(load_path=args.load_path, model='reward')
  File "/home/ec2-user/workspace/cf_rank/engine.py", line 424, in resume
    checkpoint = torch.load(load_path, map_location='cpu')
  File "/home/ec2-user/anaconda3/envs/rank3/lib/python3.9/site-packages/torch/serialization.py", line 1065, in load
    with _open_file_like(f, 'rb') as opened_file:
  File "/home/ec2-user/anaconda3/envs/rank3/lib/python3.9/site-packages/torch/serialization.py", line 468, in _open_file_like
    return _open_file(name_or_buffer, mode)
  File "/home/ec2-user/anaconda3/envs/rank3/lib/python3.9/site-packages/torch/serialization.py", line 449, in __init__
    super().__init__(open(name, mode))
FileNotFoundError: [Errno 2] No such file or directory: '/home/ec2-user/workspace/outputs/rr_ips_soft_pre_2e-6/checkpoints/checkpoint35.pth'
ERROR:root:An error occurred:
Traceback (most recent call last):
  File "/home/ec2-user/workspace/cf_rank/main.py", line 243, in <module>
    main(args)
  File "/home/ec2-user/workspace/cf_rank/main.py", line 205, in main
    trainer.resume(load_path=args.load_path, model='reward')
  File "/home/ec2-user/workspace/cf_rank/engine.py", line 424, in resume
    checkpoint = torch.load(load_path, map_location='cpu')
  File "/home/ec2-user/anaconda3/envs/rank3/lib/python3.9/site-packages/torch/serialization.py", line 1065, in load
    with _open_file_like(f, 'rb') as opened_file:
  File "/home/ec2-user/anaconda3/envs/rank3/lib/python3.9/site-packages/torch/serialization.py", line 468, in _open_file_like
    return _open_file(name_or_buffer, mode)
  File "/home/ec2-user/anaconda3/envs/rank3/lib/python3.9/site-packages/torch/serialization.py", line 449, in __init__
    super().__init__(open(name, mode))
FileNotFoundError: [Errno 2] No such file or directory: '/home/ec2-user/workspace/outputs/rr_ips_soft_pre_2e-6/checkpoints/checkpoint35.pth'
ERROR:root:An error occurred:
Traceback (most recent call last):
  File "/home/ec2-user/workspace/cf_rank/main.py", line 243, in <module>
    main(args)
  File "/home/ec2-user/workspace/cf_rank/main.py", line 205, in main
    trainer.resume(load_path=args.load_path, model='reward')
  File "/home/ec2-user/workspace/cf_rank/engine.py", line 424, in resume
    checkpoint = torch.load(load_path, map_location='cpu')
  File "/home/ec2-user/anaconda3/envs/rank3/lib/python3.9/site-packages/torch/serialization.py", line 1065, in load
    with _open_file_like(f, 'rb') as opened_file:
  File "/home/ec2-user/anaconda3/envs/rank3/lib/python3.9/site-packages/torch/serialization.py", line 468, in _open_file_like
    return _open_file(name_or_buffer, mode)
  File "/home/ec2-user/anaconda3/envs/rank3/lib/python3.9/site-packages/torch/serialization.py", line 449, in __init__
    super().__init__(open(name, mode))
FileNotFoundError: [Errno 2] No such file or directory: '/home/ec2-user/workspace/outputs/rr_ips_soft_pre_2e-6/checkpoints/checkpoint35.pth'
ERROR:root:An error occurred:
Traceback (most recent call last):
  File "/home/ec2-user/workspace/cf_rank/main.py", line 243, in <module>
    main(args)
  File "/home/ec2-user/workspace/cf_rank/main.py", line 205, in main
    trainer.resume(load_path=args.load_path, model='reward')
  File "/home/ec2-user/workspace/cf_rank/engine.py", line 424, in resume
    checkpoint = torch.load(load_path, map_location='cpu')
  File "/home/ec2-user/anaconda3/envs/rank3/lib/python3.9/site-packages/torch/serialization.py", line 1065, in load
    with _open_file_like(f, 'rb') as opened_file:
  File "/home/ec2-user/anaconda3/envs/rank3/lib/python3.9/site-packages/torch/serialization.py", line 468, in _open_file_like
    return _open_file(name_or_buffer, mode)
  File "/home/ec2-user/anaconda3/envs/rank3/lib/python3.9/site-packages/torch/serialization.py", line 449, in __init__
    super().__init__(open(name, mode))
FileNotFoundError: [Errno 2] No such file or directory: '/home/ec2-user/workspace/outputs/rr_ips_soft_pre_2e-6/checkpoints/checkpoint35.pth'
ERROR:root:An error occurred:
Traceback (most recent call last):
  File "/home/ec2-user/workspace/cf_rank/main.py", line 243, in <module>
    main(args)
  File "/home/ec2-user/workspace/cf_rank/main.py", line 205, in main
    trainer.resume(load_path=args.load_path, model='reward')
  File "/home/ec2-user/workspace/cf_rank/engine.py", line 424, in resume
    checkpoint = torch.load(load_path, map_location='cpu')
  File "/home/ec2-user/anaconda3/envs/rank3/lib/python3.9/site-packages/torch/serialization.py", line 1065, in load
    with _open_file_like(f, 'rb') as opened_file:
  File "/home/ec2-user/anaconda3/envs/rank3/lib/python3.9/site-packages/torch/serialization.py", line 468, in _open_file_like
    return _open_file(name_or_buffer, mode)
  File "/home/ec2-user/anaconda3/envs/rank3/lib/python3.9/site-packages/torch/serialization.py", line 449, in __init__
    super().__init__(open(name, mode))
FileNotFoundError: [Errno 2] No such file or directory: '/home/ec2-user/workspace/outputs/rr_ips_soft_pre_2e-6/checkpoints/checkpoint35.pth'
