ERROR:root:An error occurred:
Traceback (most recent call last):
  File "/home/ec2-user/workspace/cf_rank/main.py", line 233, in <module>
    main(args)
  File "/home/ec2-user/workspace/cf_rank/main.py", line 196, in main
    trainer.resume(load_path=args.load_path, model='reward')
  File "/home/ec2-user/workspace/cf_rank/engine.py", line 406, in resume
    checkpoint = torch.load(load_path, map_location='cpu')
  File "/home/ec2-user/anaconda3/envs/rank3/lib/python3.9/site-packages/torch/serialization.py", line 1065, in load
    with _open_file_like(f, 'rb') as opened_file:
  File "/home/ec2-user/anaconda3/envs/rank3/lib/python3.9/site-packages/torch/serialization.py", line 468, in _open_file_like
    return _open_file(name_or_buffer, mode)
  File "/home/ec2-user/anaconda3/envs/rank3/lib/python3.9/site-packages/torch/serialization.py", line 449, in __init__
    super().__init__(open(name, mode))
FileNotFoundError: [Errno 2] No such file or directory: '/home/ec2-user/workspace/outputs/rr_ips_hard_pre_2e-6/checkpoints/checkpoint15.pth'
ERROR:root:An error occurred:
Traceback (most recent call last):
  File "/home/ec2-user/workspace/cf_rank/main.py", line 233, in <module>
    main(args)
  File "/home/ec2-user/workspace/cf_rank/main.py", line 197, in main
    pyl_trainer.validate(trainer,test_dataloader)
  File "/home/ec2-user/anaconda3/envs/rank3/lib/python3.9/site-packages/pytorch_lightning/trainer/trainer.py", line 639, in validate
    return call._call_and_handle_interrupt(
  File "/home/ec2-user/anaconda3/envs/rank3/lib/python3.9/site-packages/pytorch_lightning/trainer/call.py", line 46, in _call_and_handle_interrupt
    return trainer.strategy.launcher.launch(trainer_fn, *args, trainer=trainer, **kwargs)
  File "/home/ec2-user/anaconda3/envs/rank3/lib/python3.9/site-packages/pytorch_lightning/strategies/launchers/subprocess_script.py", line 105, in launch
    return function(*args, **kwargs)
  File "/home/ec2-user/anaconda3/envs/rank3/lib/python3.9/site-packages/pytorch_lightning/trainer/trainer.py", line 679, in _validate_impl
    results = self._run(model, ckpt_path=ckpt_path)
  File "/home/ec2-user/anaconda3/envs/rank3/lib/python3.9/site-packages/pytorch_lightning/trainer/trainer.py", line 981, in _run
    results = self._run_stage()
  File "/home/ec2-user/anaconda3/envs/rank3/lib/python3.9/site-packages/pytorch_lightning/trainer/trainer.py", line 1018, in _run_stage
    return self._evaluation_loop.run()
  File "/home/ec2-user/anaconda3/envs/rank3/lib/python3.9/site-packages/pytorch_lightning/loops/utilities.py", line 178, in _decorator
    return loop_run(self, *args, **kwargs)
  File "/home/ec2-user/anaconda3/envs/rank3/lib/python3.9/site-packages/pytorch_lightning/loops/evaluation_loop.py", line 135, in run
    self._evaluation_step(batch, batch_idx, dataloader_idx, dataloader_iter)
  File "/home/ec2-user/anaconda3/envs/rank3/lib/python3.9/site-packages/pytorch_lightning/loops/evaluation_loop.py", line 396, in _evaluation_step
    output = call._call_strategy_hook(trainer, hook_name, *step_args)
  File "/home/ec2-user/anaconda3/envs/rank3/lib/python3.9/site-packages/pytorch_lightning/trainer/call.py", line 319, in _call_strategy_hook
    output = fn(*args, **kwargs)
  File "/home/ec2-user/anaconda3/envs/rank3/lib/python3.9/site-packages/pytorch_lightning/strategies/strategy.py", line 411, in validation_step
    return self.lightning_module.validation_step(*args, **kwargs)
  File "/home/ec2-user/workspace/cf_rank/engine.py", line 276, in validation_step
    out_dict, labels = self.common_step(batch, batch_idx)
  File "/home/ec2-user/workspace/cf_rank/engine.py", line 214, in common_step
    return out, avg_click
  File "/home/ec2-user/workspace/cf_rank/engine.py", line 214, in common_step
    return out, avg_click
  File "/home/ec2-user/anaconda3/envs/rank3/lib/python3.9/bdb.py", line 88, in trace_dispatch
    return self.dispatch_line(frame)
  File "/home/ec2-user/anaconda3/envs/rank3/lib/python3.9/bdb.py", line 113, in dispatch_line
    if self.quitting: raise BdbQuit
bdb.BdbQuit
ERROR:root:An error occurred:
Traceback (most recent call last):
  File "/home/ec2-user/workspace/cf_rank/main.py", line 233, in <module>
    args.limit_test_batches=None
  File "/home/ec2-user/workspace/cf_rank/main.py", line 205, in main
    trainer.resume(load_path=args.load_path, model='reward')
  File "/home/ec2-user/workspace/cf_rank/engine.py", line 511, in plot_train_val
    val_acc_match = re.search(val_acc_pattern, line)
  File "/home/ec2-user/anaconda3/envs/rank3/lib/python3.9/site-packages/matplotlib/pyplot.py", line 3794, in plot
    return gca().plot(
  File "/home/ec2-user/anaconda3/envs/rank3/lib/python3.9/site-packages/matplotlib/axes/_axes.py", line 1779, in plot
    lines = [*self._get_lines(self, *args, data=data, **kwargs)]
  File "/home/ec2-user/anaconda3/envs/rank3/lib/python3.9/site-packages/matplotlib/axes/_base.py", line 296, in __call__
    yield from self._plot_args(
  File "/home/ec2-user/anaconda3/envs/rank3/lib/python3.9/site-packages/matplotlib/axes/_base.py", line 486, in _plot_args
    raise ValueError(f"x and y must have same first dimension, but "
ValueError: x and y must have same first dimension, but have shapes (0,) and (25,)
ERROR:root:An error occurred:
Traceback (most recent call last):
  File "/home/ec2-user/workspace/cf_rank/main.py", line 243, in <module>
    main(args)
  File "/home/ec2-user/workspace/cf_rank/main.py", line 205, in main
    trainer.resume(load_path=args.load_path, model='reward')
  File "/home/ec2-user/workspace/cf_rank/engine.py", line 424, in resume
    checkpoint = torch.load(load_path, map_location='cpu')
  File "/home/ec2-user/anaconda3/envs/rank3/lib/python3.9/site-packages/torch/serialization.py", line 1065, in load
    with _open_file_like(f, 'rb') as opened_file:
  File "/home/ec2-user/anaconda3/envs/rank3/lib/python3.9/site-packages/torch/serialization.py", line 468, in _open_file_like
    return _open_file(name_or_buffer, mode)
  File "/home/ec2-user/anaconda3/envs/rank3/lib/python3.9/site-packages/torch/serialization.py", line 449, in __init__
    super().__init__(open(name, mode))
FileNotFoundError: [Errno 2] No such file or directory: '/home/ec2-user/workspace/outputs/rr_ips_hard_pre_2e-6/checkpoints/checkpoint35.pth'
ERROR:root:An error occurred:
Traceback (most recent call last):
  File "/home/ec2-user/workspace/cf_rank/main.py", line 243, in <module>
    main(args)
  File "/home/ec2-user/workspace/cf_rank/main.py", line 205, in main
    trainer.resume(load_path=args.load_path, model='reward')
  File "/home/ec2-user/workspace/cf_rank/engine.py", line 424, in resume
    checkpoint = torch.load(load_path, map_location='cpu')
  File "/home/ec2-user/anaconda3/envs/rank3/lib/python3.9/site-packages/torch/serialization.py", line 1065, in load
    with _open_file_like(f, 'rb') as opened_file:
  File "/home/ec2-user/anaconda3/envs/rank3/lib/python3.9/site-packages/torch/serialization.py", line 468, in _open_file_like
    return _open_file(name_or_buffer, mode)
  File "/home/ec2-user/anaconda3/envs/rank3/lib/python3.9/site-packages/torch/serialization.py", line 449, in __init__
    super().__init__(open(name, mode))
FileNotFoundError: [Errno 2] No such file or directory: '/home/ec2-user/workspace/outputs/rr_ips_hard_pre_2e-6/checkpoints/checkpoint35.pth'
ERROR:root:An error occurred:
Traceback (most recent call last):
  File "/home/ec2-user/workspace/cf_rank/main.py", line 243, in <module>
    main(args)
  File "/home/ec2-user/workspace/cf_rank/main.py", line 205, in main
    trainer.resume(load_path=args.load_path, model='reward')
  File "/home/ec2-user/workspace/cf_rank/engine.py", line 424, in resume
    checkpoint = torch.load(load_path, map_location='cpu')
  File "/home/ec2-user/anaconda3/envs/rank3/lib/python3.9/site-packages/torch/serialization.py", line 1065, in load
    with _open_file_like(f, 'rb') as opened_file:
  File "/home/ec2-user/anaconda3/envs/rank3/lib/python3.9/site-packages/torch/serialization.py", line 468, in _open_file_like
    return _open_file(name_or_buffer, mode)
  File "/home/ec2-user/anaconda3/envs/rank3/lib/python3.9/site-packages/torch/serialization.py", line 449, in __init__
    super().__init__(open(name, mode))
FileNotFoundError: [Errno 2] No such file or directory: '/home/ec2-user/workspace/outputs/rr_ips_hard_pre_2e-6/checkpoints/checkpoint35.pth'
ERROR:root:An error occurred:
Traceback (most recent call last):
  File "/home/ec2-user/workspace/cf_rank/main.py", line 243, in <module>
    main(args)
  File "/home/ec2-user/workspace/cf_rank/main.py", line 205, in main
    trainer.resume(load_path=args.load_path, model='reward')
  File "/home/ec2-user/workspace/cf_rank/engine.py", line 424, in resume
    checkpoint = torch.load(load_path, map_location='cpu')
  File "/home/ec2-user/anaconda3/envs/rank3/lib/python3.9/site-packages/torch/serialization.py", line 1065, in load
    with _open_file_like(f, 'rb') as opened_file:
  File "/home/ec2-user/anaconda3/envs/rank3/lib/python3.9/site-packages/torch/serialization.py", line 468, in _open_file_like
    return _open_file(name_or_buffer, mode)
  File "/home/ec2-user/anaconda3/envs/rank3/lib/python3.9/site-packages/torch/serialization.py", line 449, in __init__
    super().__init__(open(name, mode))
FileNotFoundError: [Errno 2] No such file or directory: '/home/ec2-user/workspace/outputs/rr_ips_hard_pre_2e-6/checkpoints/checkpoint35.pth'
ERROR:root:An error occurred:
Traceback (most recent call last):
  File "/home/ec2-user/workspace/cf_rank/main.py", line 243, in <module>
    main(args)
  File "/home/ec2-user/workspace/cf_rank/main.py", line 205, in main
    trainer.resume(load_path=args.load_path, model='reward')
  File "/home/ec2-user/workspace/cf_rank/engine.py", line 424, in resume
    checkpoint = torch.load(load_path, map_location='cpu')
  File "/home/ec2-user/anaconda3/envs/rank3/lib/python3.9/site-packages/torch/serialization.py", line 1065, in load
    with _open_file_like(f, 'rb') as opened_file:
  File "/home/ec2-user/anaconda3/envs/rank3/lib/python3.9/site-packages/torch/serialization.py", line 468, in _open_file_like
    return _open_file(name_or_buffer, mode)
  File "/home/ec2-user/anaconda3/envs/rank3/lib/python3.9/site-packages/torch/serialization.py", line 449, in __init__
    super().__init__(open(name, mode))
FileNotFoundError: [Errno 2] No such file or directory: '/home/ec2-user/workspace/outputs/rr_ips_hard_pre_2e-6/checkpoints/checkpoint35.pth'
