ERROR:root:An error occurred:
Traceback (most recent call last):
  File "/home/ec2-user/workspace/cf_rank/main.py", line 237, in <module>
    main(args)
  File "/home/ec2-user/workspace/cf_rank/main.py", line 199, in main
    pyl_trainer.validate(trainer,test_dataloader)
  File "/home/ec2-user/anaconda3/envs/rank3/lib/python3.9/site-packages/pytorch_lightning/trainer/trainer.py", line 639, in validate
    return call._call_and_handle_interrupt(
  File "/home/ec2-user/anaconda3/envs/rank3/lib/python3.9/site-packages/pytorch_lightning/trainer/call.py", line 46, in _call_and_handle_interrupt
    return trainer.strategy.launcher.launch(trainer_fn, *args, trainer=trainer, **kwargs)
  File "/home/ec2-user/anaconda3/envs/rank3/lib/python3.9/site-packages/pytorch_lightning/strategies/launchers/subprocess_script.py", line 105, in launch
    return function(*args, **kwargs)
  File "/home/ec2-user/anaconda3/envs/rank3/lib/python3.9/site-packages/pytorch_lightning/trainer/trainer.py", line 679, in _validate_impl
    results = self._run(model, ckpt_path=ckpt_path)
  File "/home/ec2-user/anaconda3/envs/rank3/lib/python3.9/site-packages/pytorch_lightning/trainer/trainer.py", line 981, in _run
    results = self._run_stage()
  File "/home/ec2-user/anaconda3/envs/rank3/lib/python3.9/site-packages/pytorch_lightning/trainer/trainer.py", line 1018, in _run_stage
    return self._evaluation_loop.run()
  File "/home/ec2-user/anaconda3/envs/rank3/lib/python3.9/site-packages/pytorch_lightning/loops/utilities.py", line 178, in _decorator
    return loop_run(self, *args, **kwargs)
  File "/home/ec2-user/anaconda3/envs/rank3/lib/python3.9/site-packages/pytorch_lightning/loops/evaluation_loop.py", line 135, in run
    self._evaluation_step(batch, batch_idx, dataloader_idx, dataloader_iter)
  File "/home/ec2-user/anaconda3/envs/rank3/lib/python3.9/site-packages/pytorch_lightning/loops/evaluation_loop.py", line 396, in _evaluation_step
    output = call._call_strategy_hook(trainer, hook_name, *step_args)
  File "/home/ec2-user/anaconda3/envs/rank3/lib/python3.9/site-packages/pytorch_lightning/trainer/call.py", line 319, in _call_strategy_hook
    output = fn(*args, **kwargs)
  File "/home/ec2-user/anaconda3/envs/rank3/lib/python3.9/site-packages/pytorch_lightning/strategies/strategy.py", line 411, in validation_step
    return self.lightning_module.validation_step(*args, **kwargs)
  File "/home/ec2-user/workspace/cf_rank/engine.py", line 319, in validation_step
    out_dict = self.common_step(batch, batch_idx)
  File "/home/ec2-user/workspace/cf_rank/engine.py", line 218, in common_step
    eval_ultr(batch=batch, pred_scores=logits, ips_model=self.ips_model, device=self.device)
UnboundLocalError: local variable 'logits' referenced before assignment
ERROR:root:An error occurred:
Traceback (most recent call last):
  File "/home/ec2-user/workspace/cf_rank/main.py", line 237, in <module>
    main(args)
  File "/home/ec2-user/workspace/cf_rank/main.py", line 199, in main
    pyl_trainer.validate(trainer,test_dataloader)
  File "/home/ec2-user/anaconda3/envs/rank3/lib/python3.9/site-packages/pytorch_lightning/trainer/trainer.py", line 639, in validate
    return call._call_and_handle_interrupt(
  File "/home/ec2-user/anaconda3/envs/rank3/lib/python3.9/site-packages/pytorch_lightning/trainer/call.py", line 46, in _call_and_handle_interrupt
    return trainer.strategy.launcher.launch(trainer_fn, *args, trainer=trainer, **kwargs)
  File "/home/ec2-user/anaconda3/envs/rank3/lib/python3.9/site-packages/pytorch_lightning/strategies/launchers/subprocess_script.py", line 105, in launch
    return function(*args, **kwargs)
  File "/home/ec2-user/anaconda3/envs/rank3/lib/python3.9/site-packages/pytorch_lightning/trainer/trainer.py", line 679, in _validate_impl
    results = self._run(model, ckpt_path=ckpt_path)
  File "/home/ec2-user/anaconda3/envs/rank3/lib/python3.9/site-packages/pytorch_lightning/trainer/trainer.py", line 981, in _run
    results = self._run_stage()
  File "/home/ec2-user/anaconda3/envs/rank3/lib/python3.9/site-packages/pytorch_lightning/trainer/trainer.py", line 1018, in _run_stage
    return self._evaluation_loop.run()
  File "/home/ec2-user/anaconda3/envs/rank3/lib/python3.9/site-packages/pytorch_lightning/loops/utilities.py", line 178, in _decorator
    return loop_run(self, *args, **kwargs)
  File "/home/ec2-user/anaconda3/envs/rank3/lib/python3.9/site-packages/pytorch_lightning/loops/evaluation_loop.py", line 135, in run
    self._evaluation_step(batch, batch_idx, dataloader_idx, dataloader_iter)
  File "/home/ec2-user/anaconda3/envs/rank3/lib/python3.9/site-packages/pytorch_lightning/loops/evaluation_loop.py", line 396, in _evaluation_step
    output = call._call_strategy_hook(trainer, hook_name, *step_args)
  File "/home/ec2-user/anaconda3/envs/rank3/lib/python3.9/site-packages/pytorch_lightning/trainer/call.py", line 319, in _call_strategy_hook
    output = fn(*args, **kwargs)
  File "/home/ec2-user/anaconda3/envs/rank3/lib/python3.9/site-packages/pytorch_lightning/strategies/strategy.py", line 411, in validation_step
    return self.lightning_module.validation_step(*args, **kwargs)
  File "/home/ec2-user/workspace/cf_rank/engine.py", line 319, in validation_step
    out_dict = self.common_step(batch, batch_idx)
  File "/home/ec2-user/workspace/cf_rank/engine.py", line 218, in common_step
    eval_ultr(batch=batch, pred_scores=logits, ips_model=self.ips_model, device=self.device)
UnboundLocalError: local variable 'logits' referenced before assignment
ERROR:root:An error occurred:
Traceback (most recent call last):
  File "/home/ec2-user/workspace/cf_rank/main.py", line 237, in <module>
    main(args)
  File "/home/ec2-user/workspace/cf_rank/main.py", line 199, in main
    pyl_trainer.validate(trainer,test_dataloader)
  File "/home/ec2-user/anaconda3/envs/rank3/lib/python3.9/site-packages/pytorch_lightning/trainer/trainer.py", line 639, in validate
    return call._call_and_handle_interrupt(
  File "/home/ec2-user/anaconda3/envs/rank3/lib/python3.9/site-packages/pytorch_lightning/trainer/call.py", line 46, in _call_and_handle_interrupt
    return trainer.strategy.launcher.launch(trainer_fn, *args, trainer=trainer, **kwargs)
  File "/home/ec2-user/anaconda3/envs/rank3/lib/python3.9/site-packages/pytorch_lightning/strategies/launchers/subprocess_script.py", line 105, in launch
    return function(*args, **kwargs)
  File "/home/ec2-user/anaconda3/envs/rank3/lib/python3.9/site-packages/pytorch_lightning/trainer/trainer.py", line 679, in _validate_impl
    results = self._run(model, ckpt_path=ckpt_path)
  File "/home/ec2-user/anaconda3/envs/rank3/lib/python3.9/site-packages/pytorch_lightning/trainer/trainer.py", line 981, in _run
    results = self._run_stage()
  File "/home/ec2-user/anaconda3/envs/rank3/lib/python3.9/site-packages/pytorch_lightning/trainer/trainer.py", line 1018, in _run_stage
    return self._evaluation_loop.run()
  File "/home/ec2-user/anaconda3/envs/rank3/lib/python3.9/site-packages/pytorch_lightning/loops/utilities.py", line 178, in _decorator
    return loop_run(self, *args, **kwargs)
  File "/home/ec2-user/anaconda3/envs/rank3/lib/python3.9/site-packages/pytorch_lightning/loops/evaluation_loop.py", line 135, in run
    self._evaluation_step(batch, batch_idx, dataloader_idx, dataloader_iter)
  File "/home/ec2-user/anaconda3/envs/rank3/lib/python3.9/site-packages/pytorch_lightning/loops/evaluation_loop.py", line 396, in _evaluation_step
    output = call._call_strategy_hook(trainer, hook_name, *step_args)
  File "/home/ec2-user/anaconda3/envs/rank3/lib/python3.9/site-packages/pytorch_lightning/trainer/call.py", line 319, in _call_strategy_hook
    output = fn(*args, **kwargs)
  File "/home/ec2-user/anaconda3/envs/rank3/lib/python3.9/site-packages/pytorch_lightning/strategies/strategy.py", line 411, in validation_step
    return self.lightning_module.validation_step(*args, **kwargs)
  File "/home/ec2-user/workspace/cf_rank/engine.py", line 319, in validation_step
    out_dict = self.common_step(batch, batch_idx)
  File "/home/ec2-user/workspace/cf_rank/engine.py", line 218, in common_step
    eval_ultr(batch=batch, pred_scores=logits, ips_model=self.ips_model, device=self.device)
UnboundLocalError: local variable 'logits' referenced before assignment
ERROR:root:An error occurred:
Traceback (most recent call last):
  File "/home/ec2-user/workspace/cf_rank/main.py", line 237, in <module>
    main(args)
  File "/home/ec2-user/workspace/cf_rank/main.py", line 199, in main
    pyl_trainer.validate(trainer,test_dataloader)
  File "/home/ec2-user/anaconda3/envs/rank3/lib/python3.9/site-packages/pytorch_lightning/trainer/trainer.py", line 639, in validate
    return call._call_and_handle_interrupt(
  File "/home/ec2-user/anaconda3/envs/rank3/lib/python3.9/site-packages/pytorch_lightning/trainer/call.py", line 46, in _call_and_handle_interrupt
    return trainer.strategy.launcher.launch(trainer_fn, *args, trainer=trainer, **kwargs)
  File "/home/ec2-user/anaconda3/envs/rank3/lib/python3.9/site-packages/pytorch_lightning/strategies/launchers/subprocess_script.py", line 105, in launch
    return function(*args, **kwargs)
  File "/home/ec2-user/anaconda3/envs/rank3/lib/python3.9/site-packages/pytorch_lightning/trainer/trainer.py", line 679, in _validate_impl
    results = self._run(model, ckpt_path=ckpt_path)
  File "/home/ec2-user/anaconda3/envs/rank3/lib/python3.9/site-packages/pytorch_lightning/trainer/trainer.py", line 981, in _run
    results = self._run_stage()
  File "/home/ec2-user/anaconda3/envs/rank3/lib/python3.9/site-packages/pytorch_lightning/trainer/trainer.py", line 1018, in _run_stage
    return self._evaluation_loop.run()
  File "/home/ec2-user/anaconda3/envs/rank3/lib/python3.9/site-packages/pytorch_lightning/loops/utilities.py", line 178, in _decorator
    return loop_run(self, *args, **kwargs)
  File "/home/ec2-user/anaconda3/envs/rank3/lib/python3.9/site-packages/pytorch_lightning/loops/evaluation_loop.py", line 135, in run
    self._evaluation_step(batch, batch_idx, dataloader_idx, dataloader_iter)
  File "/home/ec2-user/anaconda3/envs/rank3/lib/python3.9/site-packages/pytorch_lightning/loops/evaluation_loop.py", line 396, in _evaluation_step
    output = call._call_strategy_hook(trainer, hook_name, *step_args)
  File "/home/ec2-user/anaconda3/envs/rank3/lib/python3.9/site-packages/pytorch_lightning/trainer/call.py", line 319, in _call_strategy_hook
    output = fn(*args, **kwargs)
  File "/home/ec2-user/anaconda3/envs/rank3/lib/python3.9/site-packages/pytorch_lightning/strategies/strategy.py", line 411, in validation_step
    return self.lightning_module.validation_step(*args, **kwargs)
  File "/home/ec2-user/workspace/cf_rank/engine.py", line 319, in validation_step
    out_dict = self.common_step(batch, batch_idx)
  File "/home/ec2-user/workspace/cf_rank/engine.py", line 218, in common_step
    eval_ultr(batch=batch, pred_scores=logits, ips_model=self.ips_model, device=self.device)
UnboundLocalError: local variable 'logits' referenced before assignment
ERROR:root:An error occurred:
Traceback (most recent call last):
  File "/home/ec2-user/workspace/cf_rank/main.py", line 237, in <module>
    main(args)
  File "/home/ec2-user/workspace/cf_rank/main.py", line 199, in main
    pyl_trainer.validate(trainer,test_dataloader)
  File "/home/ec2-user/anaconda3/envs/rank3/lib/python3.9/site-packages/pytorch_lightning/trainer/trainer.py", line 639, in validate
    return call._call_and_handle_interrupt(
  File "/home/ec2-user/anaconda3/envs/rank3/lib/python3.9/site-packages/pytorch_lightning/trainer/call.py", line 46, in _call_and_handle_interrupt
    return trainer.strategy.launcher.launch(trainer_fn, *args, trainer=trainer, **kwargs)
  File "/home/ec2-user/anaconda3/envs/rank3/lib/python3.9/site-packages/pytorch_lightning/strategies/launchers/subprocess_script.py", line 105, in launch
    return function(*args, **kwargs)
  File "/home/ec2-user/anaconda3/envs/rank3/lib/python3.9/site-packages/pytorch_lightning/trainer/trainer.py", line 679, in _validate_impl
    results = self._run(model, ckpt_path=ckpt_path)
  File "/home/ec2-user/anaconda3/envs/rank3/lib/python3.9/site-packages/pytorch_lightning/trainer/trainer.py", line 981, in _run
    results = self._run_stage()
  File "/home/ec2-user/anaconda3/envs/rank3/lib/python3.9/site-packages/pytorch_lightning/trainer/trainer.py", line 1018, in _run_stage
    return self._evaluation_loop.run()
  File "/home/ec2-user/anaconda3/envs/rank3/lib/python3.9/site-packages/pytorch_lightning/loops/utilities.py", line 178, in _decorator
    return loop_run(self, *args, **kwargs)
  File "/home/ec2-user/anaconda3/envs/rank3/lib/python3.9/site-packages/pytorch_lightning/loops/evaluation_loop.py", line 135, in run
    self._evaluation_step(batch, batch_idx, dataloader_idx, dataloader_iter)
  File "/home/ec2-user/anaconda3/envs/rank3/lib/python3.9/site-packages/pytorch_lightning/loops/evaluation_loop.py", line 396, in _evaluation_step
    output = call._call_strategy_hook(trainer, hook_name, *step_args)
  File "/home/ec2-user/anaconda3/envs/rank3/lib/python3.9/site-packages/pytorch_lightning/trainer/call.py", line 319, in _call_strategy_hook
    output = fn(*args, **kwargs)
  File "/home/ec2-user/anaconda3/envs/rank3/lib/python3.9/site-packages/pytorch_lightning/strategies/strategy.py", line 411, in validation_step
    return self.lightning_module.validation_step(*args, **kwargs)
  File "/home/ec2-user/workspace/cf_rank/engine.py", line 319, in validation_step
    out_dict = self.common_step(batch, batch_idx)
  File "/home/ec2-user/workspace/cf_rank/engine.py", line 218, in common_step
    eval_ultr(batch=batch, pred_scores=logits, ips_model=self.ips_model, device=self.device)
UnboundLocalError: local variable 'logits' referenced before assignment
ERROR:root:An error occurred:
Traceback (most recent call last):
  File "/home/ec2-user/workspace/cf_rank/main.py", line 237, in <module>
    main(args)
  File "/home/ec2-user/workspace/cf_rank/main.py", line 199, in main
    pyl_trainer.validate(trainer,test_dataloader)
  File "/home/ec2-user/anaconda3/envs/rank3/lib/python3.9/site-packages/pytorch_lightning/trainer/trainer.py", line 639, in validate
    return call._call_and_handle_interrupt(
  File "/home/ec2-user/anaconda3/envs/rank3/lib/python3.9/site-packages/pytorch_lightning/trainer/call.py", line 46, in _call_and_handle_interrupt
    return trainer.strategy.launcher.launch(trainer_fn, *args, trainer=trainer, **kwargs)
  File "/home/ec2-user/anaconda3/envs/rank3/lib/python3.9/site-packages/pytorch_lightning/strategies/launchers/subprocess_script.py", line 105, in launch
    return function(*args, **kwargs)
  File "/home/ec2-user/anaconda3/envs/rank3/lib/python3.9/site-packages/pytorch_lightning/trainer/trainer.py", line 679, in _validate_impl
    results = self._run(model, ckpt_path=ckpt_path)
  File "/home/ec2-user/anaconda3/envs/rank3/lib/python3.9/site-packages/pytorch_lightning/trainer/trainer.py", line 981, in _run
    results = self._run_stage()
  File "/home/ec2-user/anaconda3/envs/rank3/lib/python3.9/site-packages/pytorch_lightning/trainer/trainer.py", line 1018, in _run_stage
    return self._evaluation_loop.run()
  File "/home/ec2-user/anaconda3/envs/rank3/lib/python3.9/site-packages/pytorch_lightning/loops/utilities.py", line 178, in _decorator
    return loop_run(self, *args, **kwargs)
  File "/home/ec2-user/anaconda3/envs/rank3/lib/python3.9/site-packages/pytorch_lightning/loops/evaluation_loop.py", line 135, in run
    self._evaluation_step(batch, batch_idx, dataloader_idx, dataloader_iter)
  File "/home/ec2-user/anaconda3/envs/rank3/lib/python3.9/site-packages/pytorch_lightning/loops/evaluation_loop.py", line 396, in _evaluation_step
    output = call._call_strategy_hook(trainer, hook_name, *step_args)
  File "/home/ec2-user/anaconda3/envs/rank3/lib/python3.9/site-packages/pytorch_lightning/trainer/call.py", line 319, in _call_strategy_hook
    output = fn(*args, **kwargs)
  File "/home/ec2-user/anaconda3/envs/rank3/lib/python3.9/site-packages/pytorch_lightning/strategies/strategy.py", line 411, in validation_step
    return self.lightning_module.validation_step(*args, **kwargs)
  File "/home/ec2-user/workspace/cf_rank/engine.py", line 319, in validation_step
    out_dict = self.common_step(batch, batch_idx)
  File "/home/ec2-user/workspace/cf_rank/engine.py", line 116, in common_step
    examination = torch.tensor(batch['examination_'+self.args.ultr_models]).to(self.device)
KeyError: 'examination_ips'
